Workbook

Sheet 月別集計
A1: 月別 平日・土日 売上集計（2026年）
A3: 月 | B3: 平日 日数 | C3: 平日 売上合計 | D3: 平日 1日平均 | E3: 土日 日数 | F3: 土日 売上合計 | G3: 土日 1日平均 | H3: 総合計 | I3: 土日比率
A4: 6月 | B4: =COUNTIFS(平日!$A$2:$A$71,">="&DATE(2026,6,1),平日!$A$2:$A$71,"<"&DATE(2026,7,1)) -> 7 | C4: =SUMIFS(平日!$C$2:$C$71,平日!$A$2:$A$71,">="&DATE(2026,6,1),平日!$A$2:$A$71,"<"&DATE(2026,7,1)) -> 2666950 | D4: =IF(B4=0,0,C4/B4) -> 380992.86 | E4: =COUNTIFS(土日!$A$2:$A$28,">="&DATE(2026,6,1),土日!$A$2:$A$28,"<"&DATE(2026,7,1)) -> 3 | F4: =SUMIFS(土日!$C$2:$C$28,土日!$A$2:$A$28,">="&DATE(2026,6,1),土日!$A$2:$A$28,"<"&DATE(2026,7,1)) -> 2059900 | G4: =IF(E4=0,0,F4/E4) -> 686633.33 | H4: =C4+F4 -> 4726850 | I4: =IF(H4=0,0,F4/H4) -> 0.43578705
A5: 7月 | B5: =COUNTIFS(平日!$A$2:$A$71,">="&DATE(2026,7,1),平日!$A$2:$A$71,"<"&DATE(2026,8,1)) -> 19 | C5: =SUMIFS(平日!$C$2:$C$71,平日!$A$2:$A$71,">="&DATE(2026,7,1),平日!$A$2:$A$71,"<"&DATE(2026,8,1)) -> 8004260 | D5: =IF(B5=0,0,C5/B5) -> 421276.84 | E5: =COUNTIFS(土日!$A$2:$A$28,">="&DATE(2026,7,1),土日!$A$2:$A$28,"<"&DATE(2026,8,1)) -> 8 | F5: =SUMIFS(土日!$C$2:$C$28,土日!$A$2:$A$28,">="&DATE(2026,7,1),土日!$A$2:$A$28,"<"&DATE(2026,8,1)) -> 5812720 | G5: =IF(E5=0,0,F5/E5) -> 726590 | H5: =C5+F5 -> 13816980 | I5: =IF(H5=0,0,F5/H5) -> 0.42069396
A6: 8月 | B6: =COUNTIFS(平日!$A$2:$A$71,">="&DATE(2026,8,1),平日!$A$2:$A$71,"<"&DATE(2026,9,1)) -> 11 | C6: =SUMIFS(平日!$C$2:$C$71,平日!$A$2:$A$71,">="&DATE(2026,8,1),平日!$A$2:$A$71,"<"&DATE(2026,9,1)) -> 3704280 | D6: =IF(B6=0,0,C6/B6) -> 336752.73 | E6: =COUNTIFS(土日!$A$2:$A$28,">="&DATE(2026,8,1),土日!$A$2:$A$28,"<"&DATE(2026,9,1)) -> 4 | F6: =SUMIFS(土日!$C$2:$C$28,土日!$A$2:$A$28,">="&DATE(2026,8,1),土日!$A$2:$A$28,"<"&DATE(2026,9,1)) -> 2408450 | G6: =IF(E6=0,0,F6/E6) -> 602112.5 | H6: =C6+F6 -> 6112730 | I6: =IF(H6=0,0,F6/H6) -> 0.39400562
A7: 9月 | B7: =COUNTIFS(平日!$A$2:$A$71,">="&DATE(2026,9,1),平日!$A$2:$A$71,"<"&DATE(2026,10,1)) -> 22 | C7: =SUMIFS(平日!$C$2:$C$71,平日!$A$2:$A$71,">="&DATE(2026,9,1),平日!$A$2:$A$71,"<"&DATE(2026,10,1)) -> 6149490 | D7: =IF(B7=0,0,C7/B7) -> 279522.27 | E7: =COUNTIFS(土日!$A$2:$A$28,">="&DATE(2026,9,1),土日!$A$2:$A$28,"<"&DATE(2026,10,1)) -> 8 | F7: =SUMIFS(土日!$C$2:$C$28,土日!$A$2:$A$28,">="&DATE(2026,9,1),土日!$A$2:$A$28,"<"&DATE(2026,10,1)) -> 4303390 | G7: =IF(E7=0,0,F7/E7) -> 537923.75 | H7: =C7+F7 -> 10452880 | I7: =IF(H7=0,0,F7/H7) -> 0.41169419
A8: 10月 | B8: =COUNTIFS(平日!$A$2:$A$71,">="&DATE(2026,10,1),平日!$A$2:$A$71,"<"&DATE(2026,11,1)) -> 11 | C8: =SUMIFS(平日!$C$2:$C$71,平日!$A$2:$A$71,">="&DATE(2026,10,1),平日!$A$2:$A$71,"<"&DATE(2026,11,1)) -> 2533860 | D8: =IF(B8=0,0,C8/B8) -> 230350.91 | E8: =COUNTIFS(土日!$A$2:$A$28,">="&DATE(2026,10,1),土日!$A$2:$A$28,"<"&DATE(2026,11,1)) -> 4 | F8: =SUMIFS(土日!$C$2:$C$28,土日!$A$2:$A$28,">="&DATE(2026,10,1),土日!$A$2:$A$28,"<"&DATE(2026,11,1)) -> 1937230 | G8: =IF(E8=0,0,F8/E8) -> 484307.5 | H8: =C8+F8 -> 4471090 | I8: =IF(H8=0,0,F8/H8) -> 0.43327913
A9: 合計 | B9: =SUM(B4:B8) -> 70 | C9: =SUM(C4:C8) -> 23058840 | D9: =IF(B9=0,0,C9/B9) -> 329412 | E9: =SUM(E4:E8) -> 27 | F9: =SUM(F4:F8) -> 16521690 | G9: =IF(E9=0,0,F9/E9) -> 611914.44 | H9: =SUM(H4:H8) -> 39580530 | I9: =IF(H9=0,0,F9/H9) -> 0.41741963
C10: 土日平均は平日平均の | D10: =IF(G9=0,0,G9/D9) -> 1.8575961
A12: 【注記】
A13: ・元データ：LINEグループの日次売上報告（6/21〜10/15）。区分は曜日のみで判定（祝日は「平日」側に含み、各シートの祝日列で表示）。
A14: ・6月は21日以降のみ（それ以前の日別報告がトーク履歴にないため）。
A15: ・トーク履歴に報告がない日（集計対象外）：7/21〜7/24、8/8〜8/23。そのため7月・8月の合計はLINE上の「合算」より少なくなります。
A16: ・7/26：当初 965,890 → 7/27の訂正投稿（本文「6月26日 695,890」は7月26日の誤記と判断）で 695,890 を採用。
A17: ・LINE上の「合算」には計算・転記の誤りがある箇所あり（例：7/12「6,413,938」、7/20合算が前日比で不一致、10/4合算が300円多い）。本表は日次の数値から集計し直しています。
A18: ・青字の売上は入力値。修正すると全集計に反映されます。

Sheet グラフ
A1: 平日・土日 売上グラフ
A2: 青＝平日 オレンジ＝土日（※祝日は平日に含む）
A22: → 全期間平均：平日 約33万円／土日 約61万円。土日は平日の約1.9倍。9月以降はどちらも下降傾向。
A41: ※6月は21日〜、10月は15日まで。7月(7/21〜24)・8月(8/8〜23)は報告なしの日があるため実際より少なめ。
A63: ※空白部分は報告のない期間（7/21〜24、8/8〜23）。
A83: → 平日・土日とも7月がピークで、その後は毎月下がっています。
A106: ※月曜始まりの週ごとの平均（横軸は週の月曜日）。平日・土日どちらかの報告がない週（6/15週、8/3週、10/12週、8/10週、8/17週）は除いています。
A107: ※7/20週・9/21週の平日が高いのは祝日（海の日・敬老の日など）を含むため。

Sheet 平日
A1: 日付 | B1: 曜日 | C1: 売上（円） | D1: 報告者 | E1: 祝日 | F1: 備考
A2: 46195 | B2: =MID("日月火水木金土",WEEKDAY(A2),1) -> 月 | C2: 386840 | D2: かりん
A3: 46196 | B3: =MID("日月火水木金土",WEEKDAY(A3),1) -> 火 | C3: 377840 | D3: かりん
A4: 46197 | B4: =MID("日月火水木金土",WEEKDAY(A4),1) -> 水 | C4: 428620 | D4: かりん
A5: 46198 | B5: =MID("日月火水木金土",WEEKDAY(A5),1) -> 木 | C5: 374210 | D5: 棚橋 拓馬
A6: 46199 | B6: =MID("日月火水木金土",WEEKDAY(A6),1) -> 金 | C6: 459300 | D6: 棚橋 拓馬
A7: 46202 | B7: =MID("日月火水木金土",WEEKDAY(A7),1) -> 月 | C7: 335720 | D7: 棚橋 拓馬
A8: 46203 | B8: =MID("日月火水木金土",WEEKDAY(A8),1) -> 火 | C8: 304420 | D8: もたい かずよし
A9: 46204 | B9: =MID("日月火水木金土",WEEKDAY(A9),1) -> 水 | C9: 454040 | D9: かりん
A10: 46205 | B10: =MID("日月火水木金土",WEEKDAY(A10),1) -> 木 | C10: 421760 | D10: もたい かずよし
A11: 46206 | B11: =MID("日月火水木金土",WEEKDAY(A11),1) -> 金 | C11: 526640 | D11: 棚橋 拓馬
A12: 46209 | B12: =MID("日月火水木金土",WEEKDAY(A12),1) -> 月 | C12: 294280 | D12: かりん
A13: 46210 | B13: =MID("日月火水木金土",WEEKDAY(A13),1) -> 火 | C13: 332760 | D13: かりん
... A21: 46220 | B21: =MID("日月火水木金土",WEEKDAY(A21),1) -> 金 | C21: 493180 | D21: もたい かずよし
A22: 46223 | B22: =MID("日月火水木金土",WEEKDAY(A22),1) -> 月 | C22: 597070 | D22: 棚橋 拓馬 | E22: 海の日
A23: 46230 | B23: =MID("日月火水木金土",WEEKDAY(A23),1) -> 月 | C23: 395610 | D23: 棚橋 拓馬
A24: 46231 | B24: =MID("日月火水木金土",WEEKDAY(A24),1) -> 火 | C24: 357540 | D24: 大後戸あつし
A25: 46232 | B25: =MID("日月火水木金土",WEEKDAY(A25),1) -> 水 | C25: 383270 | D25: 棚橋 拓馬
A26: 46233 | B26: =MID("日月火水木金土",WEEKDAY(A26),1) -> 木 | C26: 397380 | D26: もたい かずよし
A27: 46234 | B27: =MID("日月火水木金土",WEEKDAY(A27),1) -> 金 | C27: 533650 | D27: 大後戸あつし
A28: 46237 | B28: =MID("日月火水木金土",WEEKDAY(A28),1) -> 月 | C28: 363910 | D28: もたい かずよし
A29: 46238 | B29: =MID("日月火水木金土",WEEKDAY(A29),1) -> 火 | C29: 360990 | D29: 大後戸あつし
A30: 46239 | B30: =MID("日月火水木金土",WEEKDAY(A30),1) -> 水 | C30: 383160 | D30: 大後戸あつし
A31: 46240 | B31: =MID("日月火水木金土",WEEKDAY(A31),1) -> 木 | C31: 388830 | D31: もたい かずよし
A32: 46241 | B32: =MID("日月火水木金土",WEEKDAY(A32),1) -> 金 | C32: 449020 | D32: もたい かずよし
A33: 46258 | B33: =MID("日月火水木金土",WEEKDAY(A33),1) -> 月 | C33: 268730 | D33: もたい かずよし
A34: 46259 | B34: =MID("日月火水木金土",WEEKDAY(A34),1) -> 火 | C34: 256280 | D34: もたい かずよし
... A52: 46283 | B52: =MID("日月火水木金土",WEEKDAY(A52),1) -> 金 | C52: 278990 | D52: もたい かずよし
A53: 46286 | B53: =MID("日月火水木金土",WEEKDAY(A53),1) -> 月 | C53: 606440 | D53: 大後戸あつし | E53: 敬老の日
A54: 46287 | B54: =MID("日月火水木金土",WEEKDAY(A54),1) -> 火 | C54: 471650 | D54: 棚橋 拓馬 | E54: 国民の休日
A55: 46288 | B55: =MID("日月火水木金土",WEEKDAY(A55),1) -> 水 | C55: 425490 | D55: 大後戸あつし | E55: 秋分の日
A56: 46289 | B56: =MID("日月火水木金土",WEEKDAY(A56),1) -> 木 | C56: 223490 | D56: もたい かずよし
A57: 46290 | B57: =MID("日月火水木金土",WEEKDAY(A57),1) -> 金 | C57: 235170 | D57: もたい かずよし
A58: 46293 | B58: =MID("日月火水木金土",WEEKDAY(A58),1) -> 月 | C58: 175910 | D58: もたい かずよし
A59: 46294 | B59: =MID("日月火水木金土",WEEKDAY(A59),1) -> 火 | C59: 203590 | D59: 大後戸あつし
A60: 46295 | B60: =MID("日月火水木金土",WEEKDAY(A60),1) -> 水 | C60: 204670 | D60: 大後戸あつし
A61: 46296 | B61: =MID("日月火水木金土",WEEKDAY(A61),1) -> 木 | C61: 165390 | D61: もたい かずよし
A62: 46297 | B62: =MID("日月火水木金土",WEEKDAY(A62),1) -> 金 | C62: 250680 | D62: 大後戸あつし
A63: 46300 | B63: =MID("日月火水木金土",WEEKDAY(A63),1) -> 月 | C63: 190960 | D63: 大後戸あつし
A64: 46301 | B64: =MID("日月火水木金土",WEEKDAY(A64),1) -> 火 | C64: 237070 | D64: 大後戸あつし
...

Sheet 土日
A1: 日付 | B1: 曜日 | C1: 売上（円） | D1: 報告者 | E1: 祝日 | F1: 備考
A2: 46194 | B2: =MID("日月火水木金土",WEEKDAY(A2),1) -> 日 | C2: 636370 | D2: 棚橋 拓馬
A3: 46200 | B3: =MID("日月火水木金土",WEEKDAY(A3),1) -> 土 | C3: 716170 | D3: かりん
A4: 46201 | B4: =MID("日月火水木金土",WEEKDAY(A4),1) -> 日 | C4: 707360 | D4: 棚橋 拓馬
A5: 46207 | B5: =MID("日月火水木金土",WEEKDAY(A5),1) -> 土 | C5: 833600 | D5: 棚橋 拓馬
A6: 46208 | B6: =MID("日月火水木金土",WEEKDAY(A6),1) -> 日 | C6: 717490 | D6: かりん
A7: 46214 | B7: =MID("日月火水木金土",WEEKDAY(A7),1) -> 土 | C7: 773400 | D7: かりん
A8: 46215 | B8: =MID("日月火水木金土",WEEKDAY(A8),1) -> 日 | C8: 786550 | D8: かりん
A9: 46221 | B9: =MID("日月火水木金土",WEEKDAY(A9),1) -> 土 | C9: 652640 | D9: 棚橋 拓馬
A10: 46222 | B10: =MID("日月火水木金土",WEEKDAY(A10),1) -> 日 | C10: 737850 | D10: もたい かずよし
A11: 46228 | B11: =MID("日月火水木金土",WEEKDAY(A11),1) -> 土 | C11: 615300 | D11: もたい かずよし
A12: 46229 | B12: =MID("日月火水木金土",WEEKDAY(A12),1) -> 日 | C12: 695890 | D12: 大後戸あつし | F12: 訂正後の値（当初報告 965,890）
A13: 46235 | B13: =MID("日月火水木金土",WEEKDAY(A13),1) -> 土 | C13: 664790 | D13: 大後戸あつし
A14: 46236 | B14: =MID("日月火水木金土",WEEKDAY(A14),1) -> 日 | C14: 711580 | D14: 大後戸あつし
A15: 46263 | B15: =MID("日月火水木金土",WEEKDAY(A15),1) -> 土 | C15: 554810 | D15: 大後戸あつし
A16: 46264 | B16: =MID("日月火水木金土",WEEKDAY(A16),1) -> 日 | C16: 477270 | D16: 棚橋 拓馬
A17: 46270 | B17: =MID("日月火水木金土",WEEKDAY(A17),1) -> 土 | C17: 573870 | D17: 棚橋 拓馬
A18: 46271 | B18: =MID("日月火水木金土",WEEKDAY(A18),1) -> 日 | C18: 543590 | D18: 大後戸あつし
A19: 46277 | B19: =MID("日月火水木金土",WEEKDAY(A19),1) -> 土 | C19: 507490 | D19: 大後戸あつし
A20: 46278 | B20: =MID("日月火水木金土",WEEKDAY(A20),1) -> 日 | C20: 543290 | D20: 大後戸あつし
A21: 46284 | B21: =MID("日月火水木金土",WEEKDAY(A21),1) -> 土 | C21: 466800 | D21: 大後戸あつし
A22: 46285 | B22: =MID("日月火水木金土",WEEKDAY(A22),1) -> 日 | C22: 586850 | D22: 大後戸あつし
A23: 46291 | B23: =MID("日月火水木金土",WEEKDAY(A23),1) -> 土 | C23: 569450 | D23: 棚橋 拓馬
A24: 46292 | B24: =MID("日月火水木金土",WEEKDAY(A24),1) -> 日 | C24: 512050 | D24: 大後戸あつし
... A28: 46306 | B28: =MID("日月火水木金土",WEEKDAY(A28),1) -> 日 | C28: 498390 | D28: 大後戸あつし
A29: 合計 | C29: =SUM(C2:C28) -> 16521690
A30: 日数 | C30: =COUNT(C2:C28) -> 27
A31: 1日平均 | C31: =IF(C30=0,0,C29/C30) -> 611914.44

Sheet 日別推移データ
A1: 日付 | B1: 平日 | C1: 土日
A2: 46194 | B2: =IFERROR(INDEX(平日!$C$2:$C$71,MATCH(A2,平日!$A$2:$A$71,0)),"") | C2: =IFERROR(INDEX(土日!$C$2:$C$28,MATCH(A2,土日!$A$2:$A$28,0)),"") -> 636370
A3: 46195 | B3: =IFERROR(INDEX(平日!$C$2:$C$71,MATCH(A3,平日!$A$2:$A$71,0)),"") -> 386840 | C3: =IFERROR(INDEX(土日!$C$2:$C$28,MATCH(A3,土日!$A$2:$A$28,0)),"")
A4: 46196 | B4: =IFERROR(INDEX(平日!$C$2:$C$71,MATCH(A4,平日!$A$2:$A$71,0)),"") -> 377840 | C4: =IFERROR(INDEX(土日!$C$2:$C$28,MATCH(A4,土日!$A$2:$A$28,0)),"")
A5: 46197 | B5: =IFERROR(INDEX(平日!$C$2:$C$71,MATCH(A5,平日!$A$2:$A$71,0)),"") -> 428620 | C5: =IFERROR(INDEX(土日!$C$2:$C$28,MATCH(A5,土日!$A$2:$A$28,0)),"")
A6: 46198 | B6: =IFERROR(INDEX(平日!$C$2:$C$71,MATCH(A6,平日!$A$2:$A$71,0)),"") -> 374210 | C6: =IFERROR(INDEX(土日!$C$2:$C$28,MATCH(A6,土日!$A$2:$A$28,0)),"")
A7: 46199 | B7: =IFERROR(INDEX(平日!$C$2:$C$71,MATCH(A7,平日!$A$2:$A$71,0)),"") -> 459300 | C7: =IFERROR(INDEX(土日!$C$2:$C$28,MATCH(A7,土日!$A$2:$A$28,0)),"")
A8: 46200 | B8: =IFERROR(INDEX(平日!$C$2:$C$71,MATCH(A8,平日!$A$2:$A$71,0)),"") | C8: =IFERROR(INDEX(土日!$C$2:$C$28,MATCH(A8,土日!$A$2:$A$28,0)),"") -> 716170
A9: 46201 | B9: =IFERROR(INDEX(平日!$C$2:$C$71,MATCH(A9,平日!$A$2:$A$71,0)),"") | C9: =IFERROR(INDEX(土日!$C$2:$C$28,MATCH(A9,土日!$A$2:$A$28,0)),"") -> 707360
A10: 46202 | B10: =IFERROR(INDEX(平日!$C$2:$C$71,MATCH(A10,平日!$A$2:$A$71,0)),"") -> 335720 | C10: =IFERROR(INDEX(土日!$C$2:$C$28,MATCH(A10,土日!$A$2:$A$28,0)),"")
A11: 46203 | B11: =IFERROR(INDEX(平日!$C$2:$C$71,MATCH(A11,平日!$A$2:$A$71,0)),"") -> 304420 | C11: =IFERROR(INDEX(土日!$C$2:$C$28,MATCH(A11,土日!$A$2:$A$28,0)),"")
A12: 46204 | B12: =IFERROR(INDEX(平日!$C$2:$C$71,MATCH(A12,平日!$A$2:$A$71,0)),"") -> 454040 | C12: =IFERROR(INDEX(土日!$C$2:$C$28,MATCH(A12,土日!$A$2:$A$28,0)),"")
A13: 46205 | B13: =IFERROR(INDEX(平日!$C$2:$C$71,MATCH(A13,平日!$A$2:$A$71,0)),"") -> 421760 | C13: =IFERROR(INDEX(土日!$C$2:$C$28,MATCH(A13,土日!$A$2:$A$28,0)),"")
... A98: 46310 | B98: =IFERROR(INDEX(平日!$C$2:$C$71,MATCH(A98,平日!$A$2:$A$71,0)),"") -> 213180 | C98: =IFERROR(INDEX(土日!$C$2:$C$28,MATCH(A98,土日!$A$2:$A$28,0)),"")

Sheet 週別データ
A1: 週（月曜） | B1: 週の終わり | C1: 平日 1日平均 | D1: 土日 1日平均 | E1: グラフ用ラベル
A2: 46195 | B2: =A2+6 -> 46201 | C2: =AVERAGEIFS(平日!$C$2:$C$71,平日!$A$2:$A$71,">="&A2,平日!$A$2:$A$71,"<="&B2) -> 405362 | D2: =AVERAGEIFS(土日!$C$2:$C$28,土日!$A$2:$A$28,">="&A2,土日!$A$2:$A$28,"<="&B2) -> 711765 | E2: 6/22週
A3: 46202 | B3: =A3+6 -> 46208 | C3: =AVERAGEIFS(平日!$C$2:$C$71,平日!$A$2:$A$71,">="&A3,平日!$A$2:$A$71,"<="&B3) -> 408516 | D3: =AVERAGEIFS(土日!$C$2:$C$28,土日!$A$2:$A$28,">="&A3,土日!$A$2:$A$28,"<="&B3) -> 775545 | E3: 6/29週
A4: 46209 | B4: =A4+6 -> 46215 | C4: =AVERAGEIFS(平日!$C$2:$C$71,平日!$A$2:$A$71,">="&A4,平日!$A$2:$A$71,"<="&B4) -> 380590 | D4: =AVERAGEIFS(土日!$C$2:$C$28,土日!$A$2:$A$28,">="&A4,土日!$A$2:$A$28,"<="&B4) -> 779975 | E4: 7/6週
A5: 46216 | B5: =A5+6 -> 46222 | C5: =AVERAGEIFS(平日!$C$2:$C$71,平日!$A$2:$A$71,">="&A5,平日!$A$2:$A$71,"<="&B5) -> 406870 | D5: =AVERAGEIFS(土日!$C$2:$C$28,土日!$A$2:$A$28,">="&A5,土日!$A$2:$A$28,"<="&B5) -> 695245 | E5: 7/13週
A6: 46223 | B6: =A6+6 -> 46229 | C6: =AVERAGEIFS(平日!$C$2:$C$71,平日!$A$2:$A$71,">="&A6,平日!$A$2:$A$71,"<="&B6) -> 597070 | D6: =AVERAGEIFS(土日!$C$2:$C$28,土日!$A$2:$A$28,">="&A6,土日!$A$2:$A$28,"<="&B6) -> 655595 | E6: 7/20週
A7: 46230 | B7: =A7+6 -> 46236 | C7: =AVERAGEIFS(平日!$C$2:$C$71,平日!$A$2:$A$71,">="&A7,平日!$A$2:$A$71,"<="&B7) -> 413490 | D7: =AVERAGEIFS(土日!$C$2:$C$28,土日!$A$2:$A$28,">="&A7,土日!$A$2:$A$28,"<="&B7) -> 688185 | E7: 7/27週
A8: 46258 | B8: =A8+6 -> 46264 | C8: =AVERAGEIFS(平日!$C$2:$C$71,平日!$A$2:$A$71,">="&A8,平日!$A$2:$A$71,"<="&B8) -> 307740 | D8: =AVERAGEIFS(土日!$C$2:$C$28,土日!$A$2:$A$28,">="&A8,土日!$A$2:$A$28,"<="&B8) -> 516040 | E8: 8/24週
A9: 46265 | B9: =A9+6 -> 46271 | C9: =AVERAGEIFS(平日!$C$2:$C$71,平日!$A$2:$A$71,">="&A9,平日!$A$2:$A$71,"<="&B9) -> 227806 | D9: =AVERAGEIFS(土日!$C$2:$C$28,土日!$A$2:$A$28,">="&A9,土日!$A$2:$A$28,"<="&B9) -> 558730 | E9: 8/31週
A10: 46272 | B10: =A10+6 -> 46278 | C10: =AVERAGEIFS(平日!$C$2:$C$71,平日!$A$2:$A$71,">="&A10,平日!$A$2:$A$71,"<="&B10) -> 274202 | D10: =AVERAGEIFS(土日!$C$2:$C$28,土日!$A$2:$A$28,">="&A10,土日!$A$2:$A$28,"<="&B10) -> 525390 | E10: 9/7週
A11: 46279 | B11: =A11+6 -> 46285 | C11: =AVERAGEIFS(平日!$C$2:$C$71,平日!$A$2:$A$71,">="&A11,平日!$A$2:$A$71,"<="&B11) -> 262542 | D11: =AVERAGEIFS(土日!$C$2:$C$28,土日!$A$2:$A$28,">="&A11,土日!$A$2:$A$28,"<="&B11) -> 526825 | E11: 9/14週
A12: 46286 | B12: =A12+6 -> 46292 | C12: =AVERAGEIFS(平日!$C$2:$C$71,平日!$A$2:$A$71,">="&A12,平日!$A$2:$A$71,"<="&B12) -> 392448 | D12: =AVERAGEIFS(土日!$C$2:$C$28,土日!$A$2:$A$28,">="&A12,土日!$A$2:$A$28,"<="&B12) -> 540750 | E12: 9/21週
A13: 46293 | B13: =A13+6 -> 46299 | C13: =AVERAGEIFS(平日!$C$2:$C$71,平日!$A$2:$A$71,">="&A13,平日!$A$2:$A$71,"<="&B13) -> 200048 | D13: =AVERAGEIFS(土日!$C$2:$C$28,土日!$A$2:$A$28,">="&A13,土日!$A$2:$A$28,"<="&B13) -> 530435 | E13: 9/28週
A14: 46300 | B14: =A14+6 -> 46306 | C14: =AVERAGEIFS(平日!$C$2:$C$71,平日!$A$2:$A$71,">="&A14,平日!$A$2:$A$71,"<="&B14) -> 230212 | D14: =AVERAGEIFS(土日!$C$2:$C$28,土日!$A$2:$A$28,">="&A14,土日!$A$2:$A$28,"<="&B14) -> 438180 | E14: 10/5週
A16: ※平日・土日のどちらかの報告がない週は除外：6/15週、8/3週、10/12週
