Workbook

Sheet 月別サマリー
A1: 売上報告集計（2026年6月〜9月）
A2: 出典：LINEグループの日次売上報告。グレーの日は報告なし。月合計はLINE上の最終「月合算」を採用。
A4: 月 | B4: 月合計（LINE最終累計） | C4: 報告日数 | D4: 報告日の売上合計 | E4: 未報告日・差異分 | F4: 報告日の日平均 | G4: 平日平均 | H4: 土日祝平均 | I4: 最高日売上 | J4: 最低日売上 | K4: 前月比（月合計）
A5: 6月 | B5: 14567370 | C5: =COUNTIFS(日別データ!$B$2:$B$123,$A5,日別データ!$F$2:$F$123,">0") | D5: =SUMIFS(日別データ!$F$2:$F$123,日別データ!$B$2:$B$123,$A5) | E5: =B5-D5 | F5: =IFERROR(D5/C5,0) | G5: =IFERROR(AVERAGEIFS(日別データ!$F$2:$F$123,日別データ!$B$2:$B$123,$A5,日別データ!$E$2:$E$123,"平日"),0) | H5: =IFERROR(AVERAGEIFS(日別データ!$F$2:$F$123,日別データ!$B$2:$B$123,$A5,日別データ!$E$2:$E$123,"土日祝"),0) | I5: =SUMPRODUCT(MAX((日別データ!$B$2:$B$123=$A5)*(日別データ!$F$2:$F$123))) | J5: =_xlfn.MINIFS(日別データ!$F$2:$F$123,日別データ!$B$2:$B$123,$A5,日別データ!$F$2:$F$123,">0") | K5: -
A6: 7月 | B6: 15436550 | C6: =COUNTIFS(日別データ!$B$2:$B$123,$A6,日別データ!$F$2:$F$123,">0") | D6: =SUMIFS(日別データ!$F$2:$F$123,日別データ!$B$2:$B$123,$A6) | E6: =B6-D6 | F6: =IFERROR(D6/C6,0) | G6: =IFERROR(AVERAGEIFS(日別データ!$F$2:$F$123,日別データ!$B$2:$B$123,$A6,日別データ!$E$2:$E$123,"平日"),0) | H6: =IFERROR(AVERAGEIFS(日別データ!$F$2:$F$123,日別データ!$B$2:$B$123,$A6,日別データ!$E$2:$E$123,"土日祝"),0) | I6: =SUMPRODUCT(MAX((日別データ!$B$2:$B$123=$A6)*(日別データ!$F$2:$F$123))) | J6: =_xlfn.MINIFS(日別データ!$F$2:$F$123,日別データ!$B$2:$B$123,$A6,日別データ!$F$2:$F$123,">0") | K6: =B6/B5-1
A7: 8月 | B7: 13529470 | C7: =COUNTIFS(日別データ!$B$2:$B$123,$A7,日別データ!$F$2:$F$123,">0") | D7: =SUMIFS(日別データ!$F$2:$F$123,日別データ!$B$2:$B$123,$A7) | E7: =B7-D7 | F7: =IFERROR(D7/C7,0) | G7: =IFERROR(AVERAGEIFS(日別データ!$F$2:$F$123,日別データ!$B$2:$B$123,$A7,日別データ!$E$2:$E$123,"平日"),0) | H7: =IFERROR(AVERAGEIFS(日別データ!$F$2:$F$123,日別データ!$B$2:$B$123,$A7,日別データ!$E$2:$E$123,"土日祝"),0) | I7: =SUMPRODUCT(MAX((日別データ!$B$2:$B$123=$A7)*(日別データ!$F$2:$F$123))) | J7: =_xlfn.MINIFS(日別データ!$F$2:$F$123,日別データ!$B$2:$B$123,$A7,日別データ!$F$2:$F$123,">0") | K7: =B7/B6-1
A8: 9月 | B8: 10452880 | C8: =COUNTIFS(日別データ!$B$2:$B$123,$A8,日別データ!$F$2:$F$123,">0") | D8: =SUMIFS(日別データ!$F$2:$F$123,日別データ!$B$2:$B$123,$A8) | E8: =B8-D8 | F8: =IFERROR(D8/C8,0) | G8: =IFERROR(AVERAGEIFS(日別データ!$F$2:$F$123,日別データ!$B$2:$B$123,$A8,日別データ!$E$2:$E$123,"平日"),0) | H8: =IFERROR(AVERAGEIFS(日別データ!$F$2:$F$123,日別データ!$B$2:$B$123,$A8,日別データ!$E$2:$E$123,"土日祝"),0) | I8: =SUMPRODUCT(MAX((日別データ!$B$2:$B$123=$A8)*(日別データ!$F$2:$F$123))) | J8: =_xlfn.MINIFS(日別データ!$F$2:$F$123,日別データ!$B$2:$B$123,$A8,日別データ!$F$2:$F$123,">0") | K8: =B8/B7-1
A9: 合計 | B9: =SUM(B5:B8) | C9: =SUM(C5:C8) | D9: =SUM(D5:D8) | E9: =SUM(E5:E8)
A11: 【注記】
A12: ・6月は6/21以降のみ日別報告あり。6/1〜6/20分（9,840,520円）は「未報告日・差異分」に含まれます。
A13: ・8月は8/8〜8/23の日別報告なし（月累計から差し引くと計7,236,740円相当）。
A14: ・7月は7/21〜7/24の日別報告なし。また7/26は訂正後の695,890円を採用。
A15: ・LINE上の累計に以下の計算ズレがあります（月合計はLINE最終累計を優先）：
A16: - 7/4: 前日累計1,402,440+当日833,600=2,236,040 だがLINE累計は2,175,780（差 -60,260）
A17: - 7/8: 前日累計3,520,310+当日375,800=3,896,110 だがLINE累計は3,953,870（差 +57,760）
A18: - 7/12: 前日累計5,627,380+当日786,550=6,413,930 だがLINE累計は6,413,938（差 +8）
A19: - 7/13: 前日累計6,413,938+当日372,650=6,786,588 だがLINE累計は6,784,580（差 -2,008）
A20: - 7/20: 前日累計9,836,770+当日597,070=10,433,840 だがLINE累計は10,342,730（差 -91,110）
A21: - 7/26: 前日累計12,654,100+当日695,890=13,349,990 だがLINE累計は13,369,100（差 +19,110）

Sheet 日別データ
A1: 日付 | B1: 月 | C1: 日 | D1: 曜日 | E1: 区分 | F1: 売上（円） | G1: 報告者 | H1: LINE上の月累計（円） | I1: 備考
A2: 46174 | B2: 6月 | C2: 1 | D2: 月 | E2: 平日 | I2: 未報告（LINEに記載なし）
A3: 46175 | B3: 6月 | C3: 2 | D3: 火 | E3: 平日 | I3: 未報告（LINEに記載なし）
A4: 46176 | B4: 6月 | C4: 3 | D4: 水 | E4: 平日 | I4: 未報告（LINEに記載なし）
A5: 46177 | B5: 6月 | C5: 4 | D5: 木 | E5: 平日 | I5: 未報告（LINEに記載なし）
A6: 46178 | B6: 6月 | C6: 5 | D6: 金 | E6: 平日 | I6: 未報告（LINEに記載なし）
A7: 46179 | B7: 6月 | C7: 6 | D7: 土 | E7: 土日祝 | I7: 未報告（LINEに記載なし）
A8: 46180 | B8: 6月 | C8: 7 | D8: 日 | E8: 土日祝 | I8: 未報告（LINEに記載なし）
A9: 46181 | B9: 6月 | C9: 8 | D9: 月 | E9: 平日 | I9: 未報告（LINEに記載なし）
A10: 46182 | B10: 6月 | C10: 9 | D10: 火 | E10: 平日 | I10: 未報告（LINEに記載なし）
A11: 46183 | B11: 6月 | C11: 10 | D11: 水 | E11: 平日 | I11: 未報告（LINEに記載なし）
A12: 46184 | B12: 6月 | C12: 11 | D12: 木 | E12: 平日 | I12: 未報告（LINEに記載なし）
A13: 46185 | B13: 6月 | C13: 12 | D13: 金 | E13: 平日 | I13: 未報告（LINEに記載なし）
... A21: 46193 | B21: 6月 | C21: 20 | D21: 土 | E21: 土日祝 | I21: 未報告（LINEに記載なし）
A22: 46194 | B22: 6月 | C22: 21 | D22: 日 | E22: 土日祝 | F22: 636370 | G22: 棚橋 | H22: 10476890
A23: 46195 | B23: 6月 | C23: 22 | D23: 月 | E23: 平日 | F23: 386840 | G23: かりん | H23: 10863730
A24: 46196 | B24: 6月 | C24: 23 | D24: 火 | E24: 平日 | F24: 377840 | G24: かりん | H24: 11241570
A25: 46197 | B25: 6月 | C25: 24 | D25: 水 | E25: 平日 | F25: 428620 | G25: かりん | H25: 11670190
A26: 46198 | B26: 6月 | C26: 25 | D26: 木 | E26: 平日 | F26: 374210 | G26: 棚橋 | H26: 12044400
A27: 46199 | B27: 6月 | C27: 26 | D27: 金 | E27: 平日 | F27: 459300 | G27: 棚橋 | H27: 12503700
A28: 46200 | B28: 6月 | C28: 27 | D28: 土 | E28: 土日祝 | F28: 716170 | G28: かりん | H28: 13219870
A29: 46201 | B29: 6月 | C29: 28 | D29: 日 | E29: 土日祝 | F29: 707360 | G29: 棚橋 | H29: 13927230
A30: 46202 | B30: 6月 | C30: 29 | D30: 月 | E30: 平日 | F30: 335720 | G30: 棚橋 | H30: 14262950
A31: 46203 | B31: 6月 | C31: 30 | D31: 火 | E31: 平日 | F31: 304420 | G31: もたい | H31: 14567370
A32: 46204 | B32: 7月 | C32: 1 | D32: 水 | E32: 平日 | F32: 454040 | G32: かりん | H32: 454040
A33: 46205 | B33: 7月 | C33: 2 | D33: 木 | E33: 平日 | F33: 421760 | G33: もたい | H33: 875800
... A51: 46223 | B51: 7月 | C51: 20 | D51: 月 | E51: 土日祝 | F51: 597070 | G51: 棚橋 | H51: 10342730
A52: 46224 | B52: 7月 | C52: 21 | D52: 火 | E52: 平日 | I52: 未報告（LINEに記載なし）
A53: 46225 | B53: 7月 | C53: 22 | D53: 水 | E53: 平日 | I53: 未報告（LINEに記載なし）
A54: 46226 | B54: 7月 | C54: 23 | D54: 木 | E54: 平日 | I54: 未報告（LINEに記載なし）
A55: 46227 | B55: 7月 | C55: 24 | D55: 金 | E55: 平日 | I55: 未報告（LINEに記載なし）
A56: 46228 | B56: 7月 | C56: 25 | D56: 土 | E56: 土日祝 | F56: 615300 | G56: もたい | H56: 12654100
A57: 46229 | B57: 7月 | C57: 26 | D57: 日 | E57: 土日祝 | F57: 695890 | G57: 大後戸 | H57: 13369100 | I57: 当初965,890で報告→7/27に695,890へ訂正（訂正文では「6月26日」と記載）
A58: 46230 | B58: 7月 | C58: 27 | D58: 月 | E58: 平日 | F58: 395610 | G58: 棚橋 | H58: 13764710
A59: 46231 | B59: 7月 | C59: 28 | D59: 火 | E59: 平日 | F59: 357540 | G59: 大後戸 | H59: 14122250
A60: 46232 | B60: 7月 | C60: 29 | D60: 水 | E60: 平日 | F60: 383270 | G60: 棚橋 | H60: 14505520
A61: 46233 | B61: 7月 | C61: 30 | D61: 木 | E61: 平日 | F61: 397380 | G61: もたい | H61: 14902900
A62: 46234 | B62: 7月 | C62: 31 | D62: 金 | E62: 平日 | F62: 533650 | G62: 大後戸 | H62: 15436550
A63: 46235 | B63: 8月 | C63: 1 | D63: 土 | E63: 土日祝 | F63: 664790 | G63: 大後戸 | H63: 664790
A64: 46236 | B64: 8月 | C64: 2 | D64: 日 | E64: 土日祝 | F64: 711580 | G64: 大後戸 | H64: 1376370
...

Sheet 報告者別
A1: 報告者 | B1: 報告回数 | C1: 報告日の売上合計 | D1: 1日平均
A2: 大後戸 | B2: =COUNTIF(日別データ!$G$2:$G$123,A2) | C2: =SUMIF(日別データ!$G$2:$G$123,A2,日別データ!$F$2:$F$123) | D2: =IFERROR(C2/B2,0)
A3: もたい | B3: =COUNTIF(日別データ!$G$2:$G$123,A3) | C3: =SUMIF(日別データ!$G$2:$G$123,A3,日別データ!$F$2:$F$123) | D3: =IFERROR(C3/B3,0)
A4: 棚橋 | B4: =COUNTIF(日別データ!$G$2:$G$123,A4) | C4: =SUMIF(日別データ!$G$2:$G$123,A4,日別データ!$F$2:$F$123) | D4: =IFERROR(C4/B4,0)
A5: かりん | B5: =COUNTIF(日別データ!$G$2:$G$123,A5) | C5: =SUMIF(日別データ!$G$2:$G$123,A5,日別データ!$F$2:$F$123) | D5: =IFERROR(C5/B5,0)
A7: ※報告者＝LINEに報告を投稿した人（売上担当とは限りません）

Sheet グラフ
A1: 日 | B1: 6月 | C1: 7月 | D1: 8月 | E1: 9月
A2: 1 | C2: 454040 | D2: 664790 | E2: 228460
A3: 2 | C3: 421760 | D3: 711580 | E3: 214940
A4: 3 | C4: 526640 | D4: 363910 | E4: 263030
A5: 4 | C5: 833600 | D5: 360990 | E5: 212930
A6: 5 | C6: 717490 | D6: 383160 | E6: 573870
A7: 6 | C7: 294280 | D7: 388830 | E7: 543590
A8: 7 | C8: 332760 | D8: 449020 | E8: 207730
A9: 8 | C9: 375800 | E9: 335170
A10: 9 | C10: 425290 | E10: 212760
A11: 10 | C11: 474820 | E11: 294500
A12: 11 | C12: 773400 | E12: 320850
A13: 12 | C13: 786550 | E13: 507490
A14: 13 | C14: 372650 | E14: 543290
A15: 14 | C15: 289840 | E15: 215510
A16: 15 | C16: 418780 | E16: 167060
A17: 16 | C17: 459900 | E17: 392050
A18: 17 | C18: 493180 | E18: 259100
A19: 18 | C19: 652640 | E19: 278990
A20: 19 | C20: 737850 | E20: 466800
A21: 20 | C21: 597070 | E21: 586850
A22: 21 | B22: 636370 | E22: 606440
A23: 22 | B23: 386840 | E23: 471650
A24: 23 | B24: 377840 | E24: 425490
A25: 24 | B25: 428620 | D25: 268730 | E25: 223490
A26: 25 | B26: 374210 | C26: 615300 | D26: 256280 | E26: 235170
A27: 26 | B27: 459300 | C27: 695890 | D27: 351140 | E27: 569450
A28: 27 | B28: 716170 | C28: 395610 | D28: 299580 | E28: 512050
A29: 28 | B29: 707360 | C29: 357540 | D29: 362970 | E29: 175910
A30: 29 | B30: 335720 | C30: 383270 | D30: 554810 | E30: 203590
A31: 30 | B31: 304420 | C31: 397380 | D31: 477270 | E31: 204670
A32: 31 | C32: 533650 | D32: 219670
A34: ※日別データシートの値（未報告日は空欄＝グラフ上で途切れます）
